<?xml version="1.0" ?>
<!-- =================================================================================== -->
<!-- |    This document was autogenerated by xacro from akula.urdf.xacro               | -->
<!-- |    EDITING THIS FILE BY HAND IS NOT RECOMMENDED                                 | -->
<!-- =================================================================================== -->
<!--  
   ======================================== 
     * Author: nipun.dhananjaya@gmail.com 
     * Created: 10.03.2023 
   ======================================== 
-->
<robot name="akula">
  <link name="base_footprint"/>
  <!-- Initial Link -->
  <link name="inertial_link">
    <inertial>
      <mass value="132.3898489950015"/>
      <origin xyz="0.015 0  0.0231316650320557"/>
      <inertia ixx="0.185196122711036" ixy="0" ixz="0" iyy="0.364893736238929" iyz="-0.000386720198091934" izz="0.223868521722778"/>
    </inertial>
  </link>
  <!-- base link -->
  <link name="base_link">
    <visual>
      <origin rpy="1.57 0 0" xyz="0 0 0"/>
      <geometry>
        <mesh filename="meshes/tracer_base_link_no_wheel.dae"/>
      </geometry>
      <material name="base">
        <color rgba="0.2 0.2 0.2 1"/>
      </material>
    </visual>
    <collision>
      <origin rpy="1.57 0 0" xyz="0 0 0"/>
      <geometry>
        <mesh filename="meshes/tracer_base_link_no_wheel.dae"/>
      </geometry>
    </collision>
  </link>
  <!-- ************************************************** -->
  <!-- FL castor joint link -->
  <link name="fl_castor_link">
    <visual>
      <geometry>
        <mesh filename="meshes/castor_joint.dae"/>
      </geometry>
      <material name="fl_castor_link">
        <color rgba="0.8 0.2 0.2 1"/>
      </material>
    </visual>
    <inertial>
      <mass value="1"/>
      <origin xyz="0 0 0"/>
      <inertia ixx="0.7171" ixy="0" ixz="0" iyy="0.1361" iyz="0" izz="0.7171"/>
    </inertial>
  </link>
  <!-- FR castor joint link -->
  <link name="fr_castor_link">
    <visual>
      <geometry>
        <mesh filename="meshes/castor_joint.dae"/>
      </geometry>
      <material name="fr_castor_link">
        <color rgba="0.8 0.2 0.2 1"/>
      </material>
    </visual>
    <inertial>
      <mass value="1"/>
      <origin xyz="0 0 0"/>
      <inertia ixx="0.7171" ixy="0" ixz="0" iyy="0.1361" iyz="0" izz="0.7171"/>
    </inertial>
  </link>
  <!-- BL castor joint link -->
  <link name="bl_castor_link">
    <visual>
      <geometry>
        <mesh filename="meshes/castor_joint.dae"/>
      </geometry>
      <material name="bl_castor_link">
        <color rgba="0.8 0.2 0.2 1"/>
      </material>
    </visual>
    <inertial>
      <mass value="1"/>
      <origin xyz="0 0 0"/>
      <inertia ixx="0.7171" ixy="0" ixz="0" iyy="0.1361" iyz="0" izz="0.7171"/>
    </inertial>
  </link>
  <!-- BR castor joint link -->
  <link name="br_castor_link">
    <visual>
      <geometry>
        <mesh filename="meshes/castor_joint.dae"/>
      </geometry>
      <material name="br_castor_link">
        <color rgba="0.8 0.2 0.2 1"/>
      </material>
    </visual>
    <inertial>
      <mass value="1"/>
      <origin xyz="0 0 0"/>
      <inertia ixx="0.7171" ixy="0" ixz="0" iyy="0.1361" iyz="0" izz="0.7171"/>
    </inertial>
  </link>
  <!-- ************************************************** -->
  <!-- FL castor wheel -->
  <link name="fl_castor_wheel">
    <visual>
      <geometry>
        <cylinder length="0.04653" radius="0.036"/>
      </geometry>
      <material name="fl_castor_wheel">
        <color rgba="0.4 0.4 0.2 1"/>
      </material>
    </visual>
    <collision>
      <geometry>
        <cylinder length="0.04653" radius="0.036"/>
      </geometry>
    </collision>
    <inertial>
      <mass value="1"/>
      <origin xyz="0 0 0"/>
      <inertia ixx="0.000504" ixy="0" ixz="0" iyy="0.000504" iyz="0" izz="0.000648"/>
    </inertial>
  </link>
  <!-- FR castor wheel -->
  <link name="fr_castor_wheel">
    <visual>
      <geometry>
        <cylinder length="0.04653" radius="0.036"/>
      </geometry>
      <material name="fr_castor_wheel">
        <color rgba="0.4 0.4 0.2 1"/>
      </material>
    </visual>
    <collision>
      <geometry>
        <cylinder length="0.04653" radius="0.036"/>
      </geometry>
    </collision>
    <inertial>
      <mass value="1"/>
      <origin xyz="0 0 0"/>
      <inertia ixx="0.000504" ixy="0" ixz="0" iyy="0.000504" iyz="0" izz="0.000648"/>
    </inertial>
  </link>
  <!-- BL castor wheel -->
  <link name="bl_castor_wheel">
    <visual>
      <geometry>
        <cylinder length="0.04653" radius="0.036"/>
      </geometry>
      <material name="bl_castor_wheel">
        <color rgba="0.4 0.4 0.2 1"/>
      </material>
    </visual>
    <collision>
      <geometry>
        <cylinder length="0.04653" radius="0.036"/>
      </geometry>
    </collision>
    <inertial>
      <mass value="1"/>
      <origin xyz="0 0 0"/>
      <inertia ixx="0.000504" ixy="0" ixz="0" iyy="0.000504" iyz="0" izz="0.000648"/>
    </inertial>
  </link>
  <!-- BR castor wheel -->
  <link name="br_castor_wheel">
    <visual>
      <geometry>
        <cylinder length="0.04653" radius="0.036"/>
      </geometry>
      <material name="br_castor_wheel">
        <color rgba="0.4 0.4 0.2 1"/>
      </material>
    </visual>
    <collision>
      <geometry>
        <cylinder length="0.04653" radius="0.036"/>
      </geometry>
    </collision>
    <inertial>
      <mass value="1"/>
      <origin xyz="0 0 0"/>
      <inertia ixx="0.000504" ixy="0" ixz="0" iyy="0.000504" iyz="0" izz="0.000648"/>
    </inertial>
  </link>
  <!-- ************************************************** -->
  <link name="L_wheel">
    <visual>
      <geometry>
        <cylinder length="0.0787019" radius="0.0605"/>
      </geometry>
      <material name="L_wheel">
        <color rgba="0.1 0.1 0.1 1"/>
      </material>
      <origin rpy="1.57 0 0" xyz="0 0 0"/>
    </visual>
    <collision>
      <geometry>
        <cylinder length="0.0787019" radius="0.0605"/>
      </geometry>
      <origin rpy="1.57 0 0" xyz="0 0 0"/>
    </collision>
    <inertial>
      <mass value="6"/>
      <origin rpy="1.57 0 0" xyz="0 0 0"/>
      <inertia ixx="0.00859" ixy="0" ixz="0" iyy="0.01098" iyz="0" izz="0.00859"/>
    </inertial>
  </link>
  <link name="R_wheel">
    <visual>
      <geometry>
        <cylinder length="0.0787019" radius="0.0605"/>
      </geometry>
      <material name="R_wheel">
        <color rgba="0.1 0.1 0.1 1"/>
      </material>
      <origin rpy="1.57 0 0" xyz="0 0 0"/>
    </visual>
    <inertial>
      <mass value="6"/>
      <origin rpy="1.57 0 0" xyz="0 0 0"/>
      <inertia ixx="0.00859" ixy="0" ixz="0" iyy="0.01098" iyz="0" izz="0.00859"/>
    </inertial>
    <collision>
      <geometry>
        <cylinder length="0.0787019" radius="0.0605"/>
      </geometry>
      <origin rpy="1.57 0 0" xyz="0 0 0"/>
    </collision>
  </link>
  <link name="fin_link">
    <visual>
      <geometry>
        <mesh filename="meshes/fin.stl" scale="0.001 0.001 0.001"/>
      </geometry>
      <material name="fin">
        <color rgba="0.058 0.058 0.058 1"/>
      </material>
    </visual>
    <inertial>
      <mass value="1"/>
      <origin xyz="0 0 0"/>
      <inertia ixx="0.3" ixy="0" ixz="0" iyy="0.3" iyz="0" izz="0.3"/>
    </inertial>
    <collision>
      <geometry>
        <mesh filename="meshes/fin.stl" scale="0.001 0.001 0.001"/>
      </geometry>
    </collision>
  </link>
  <link name="camera_link">
    <visual>
      <geometry>
        <box size="0.10 0.15 0.03"/>
      </geometry>
      <material name="camera_material">
        <color rgba="0.034 0.064 0.09 0.99"/>
      </material>
    </visual>
    <collision>
      <geometry>
        <box size="0.10 0.15 0.03"/>
      </geometry>
    </collision>
    <inertial>
      <mass value="0.8"/>
      <origin xyz="0 0 0"/>
      <inertia ixx="0.0015266666666666666" ixy="0" ixz="0" iyy="0.0006933333333333335" iyz="0" izz="0.0021666666666666666"/>
    </inertial>
  </link>
  <link name="camera_optical_link">
    <inertial>
      <mass value="1e-6"/>
      <origin xyz="0 0 0"/>
      <inertia ixx="1e-9" ixy="0" ixz="0" iyy="1e-9" iyz="0" izz="1e-9"/>
    </inertial>
  </link>
  <joint name="base_footprint_joint" type="fixed">
    <parent link="base_footprint"/>
    <child link="base_link"/>
    <origin rpy="0 0 0" xyz="0 0 0"/>
  </joint>
  <joint name="base_joint" type="fixed">
    <origin rpy="0 0 0" xyz="0 0 0"/>
    <parent link="base_link"/>
    <child link="inertial_link"/>
  </joint>
  <joint name="fin_joint" type="fixed">
    <origin rpy="0 0 -1.5708" xyz="0 0 -0.15"/>
    <parent link="base_link"/>
    <child link="fin_link"/>
  </joint>
  <!-- ************************************************** -->
  <!-- FL castor -->
  <joint name="fl_castor_joint" type="continuous">
    <origin rpy="-1.57 0 0" xyz="0.18955 0.17 -0.0375886"/>
    <!-- 0.0380886 -->
    <parent link="base_link"/>
    <child link="fl_castor_link"/>
    <axis xyz="0 1 0"/>
  </joint>
  <!-- FR castor -->
  <joint name="fr_castor_joint" type="continuous">
    <origin rpy="-1.57 0 0" xyz="0.18955 -0.17 -0.0375886"/>
    <parent link="base_link"/>
    <child link="fr_castor_link"/>
    <axis xyz="0 1 0"/>
  </joint>
  <!-- BL castor -->
  <joint name="bl_castor_joint" type="continuous">
    <origin rpy="-1.57 0 0" xyz="-0.18955 0.17 -0.0375886"/>
    <parent link="base_link"/>
    <child link="bl_castor_link"/>
    <axis xyz="0 1 0"/>
  </joint>
  <!-- BR castor -->
  <joint name="br_castor_joint" type="continuous">
    <origin rpy="-1.57 0 0" xyz="-0.18955 -0.17 -0.0375886"/>
    <parent link="base_link"/>
    <child link="br_castor_link"/>
    <axis xyz="0 1 0"/>
  </joint>
  <!-- ************************************************** -->
  <!-- FL Castor wheel -->
  <joint name="fl_castor_wheel_joint" type="continuous">
    <origin rpy="0 0 0" xyz="-0.0218084 0.067 0"/>
    <parent link="fl_castor_link"/>
    <child link="fl_castor_wheel"/>
    <axis xyz="0 0 1"/>
    <dynamics damping="0.2"/>
  </joint>
  <!-- FR Castor wheel -->
  <joint name="fr_castor_wheel_joint" type="continuous">
    <origin rpy="0 0 0" xyz="-0.0218084 0.067 0"/>
    <parent link="fr_castor_link"/>
    <child link="fr_castor_wheel"/>
    <axis xyz="0 0 1"/>
    <dynamics damping="0.2"/>
  </joint>
  <!-- BL Castor wheel -->
  <joint name="bl_castor_wheel_joint" type="continuous">
    <origin rpy="0 0 0" xyz="-0.0218084 0.067 0"/>
    <parent link="bl_castor_link"/>
    <child link="bl_castor_wheel"/>
    <axis xyz="0 0 1"/>
    <dynamics damping="0.2"/>
  </joint>
  <!-- BR Castor wheel -->
  <joint name="br_castor_wheel_joint" type="continuous">
    <origin rpy="0 0 0" xyz="-0.0218084 0.067 0"/>
    <parent link="br_castor_link"/>
    <child link="br_castor_wheel"/>
    <axis xyz="0 0 1"/>
    <dynamics damping="0.2"/>
  </joint>
  <!-- ************************************************** -->
  <!-- Left wheel -->
  <joint name="L_wheel_joint" type="continuous">
    <origin rpy="0 0 0" xyz="0 0.17 -0.082"/>
    <parent link="base_link"/>
    <child link="L_wheel"/>
    <axis xyz="0 1 0"/>
    <dynamics damping="0.2"/>
  </joint>
  <!-- Right wheel -->
  <joint name="R_wheel_joint" type="continuous">
    <origin rpy="0 0 0" xyz="0 -0.17 -0.082"/>
    <parent link="base_link"/>
    <child link="R_wheel"/>
    <axis xyz="0 1 0"/>
    <dynamics damping="0.2"/>
  </joint>

  <joint name="camera_joint" type="fixed">
    <parent link="fin_link"/>
    <child link="camera_link"/>
    <origin rpy="0 0 1.5708" xyz="0 -0.14 0.84"/>
  </joint>
  <joint name="camera_optical_joint" type="fixed">
    <parent link="camera_link"/>
    <child link="camera_optical_link"/>
    <origin rpy="0 0 0" xyz="0 0 0"/>
  </joint>
  
</robot>
